<?xml version="1.0" ?>
<robot name="quad_robot" xmlns:xacro="http://www.ros.org/wiki/xacro">

<xacro:include filename="$(find quad_robot_description)/urdf/materials.xacro" />
<xacro:include filename="$(find quad_robot_description)/urdf/quad_robot.trans" />
<xacro:include filename="$(find quad_robot_description)/urdf/quad_robot.gazebo" />
<link name="base_link">
  <inertial>
    <origin xyz="-0.0700000000000002 0.08926755092273143 0.153876888013964" rpy="0 0 0"/>
    <mass value="0.685741132753167"/>
    <inertia ixx="0.000977" iyy="0.001714" izz="0.002403" ixy="-0.0" iyz="0.0" ixz="-0.0"/>
  </inertial>
  <visual>
    <origin xyz="0 0 0" rpy="0 0 0"/>
    <geometry>
      <mesh filename="file://$(find quad_robot_description)/meshes/base_link.stl" scale="0.001 0.001 0.001"/>
    </geometry>
    <material name="silver"/>
  </visual>
  <collision>
    <origin xyz="0 0 0" rpy="0 0 0"/>
    <geometry>
      <mesh filename="file://$(find quad_robot_description)/meshes/base_link.stl" scale="0.001 0.001 0.001"/>
    </geometry>
  </collision>
</link>

<link name="bl_shin_link_1">
  <inertial>
    <origin xyz="5.770905402621389e-15 0.004888703494644792 -0.03833090663339933" rpy="0 0 0"/>
    <mass value="0.07085398163397447"/>
    <inertia ixx="6e-05" iyy="5.8e-05" izz="9e-06" ixy="-0.0" iyz="0.0" ixz="-0.0"/>
  </inertial>
  <visual>
    <origin xyz="0.0 0.003232 -0.090732" rpy="0 0 0"/>
    <geometry>
      <mesh filename="file://$(find quad_robot_description)/meshes/bl_shin_link_1.stl" scale="0.001 0.001 0.001"/>
    </geometry>
    <material name="silver"/>
  </visual>
  <collision>
    <origin xyz="0.0 0.003232 -0.090732" rpy="0 0 0"/>
    <geometry>
      <mesh filename="file://$(find quad_robot_description)/meshes/bl_shin_link_1.stl" scale="0.001 0.001 0.001"/>
    </geometry>
  </collision>
</link>

<link name="bl_leg_link_1">
  <inertial>
    <origin xyz="1.4137324648158097e-14 0.006238206362926059 -0.016886305719521988" rpy="0 0 0"/>
    <mass value="0.057591261478765976"/>
    <inertia ixx="4.4e-05" iyy="4.3e-05" izz="8e-06" ixy="0.0" iyz="3e-06" ixz="0.0"/>
  </inertial>
  <visual>
    <origin xyz="0.0 -0.006768 -0.153232" rpy="0 0 0"/>
    <geometry>
      <mesh filename="file://$(find quad_robot_description)/meshes/bl_leg_link_1.stl" scale="0.001 0.001 0.001"/>
    </geometry>
    <material name="silver"/>
  </visual>
  <collision>
    <origin xyz="0.0 -0.006768 -0.153232" rpy="0 0 0"/>
    <geometry>
      <mesh filename="file://$(find quad_robot_description)/meshes/bl_leg_link_1.stl" scale="0.001 0.001 0.001"/>
    </geometry>
  </collision>
</link>

<link name="bl_thigh_link_1">
  <inertial>
    <origin xyz="0.0433271050904814 -0.0005974221436028312 -0.013857298738867513" rpy="0 0 0"/>
    <mass value="0.05920353755551334"/>
    <inertia ixx="1.4e-05" iyy="2.3e-05" izz="1.6e-05" ixy="0.0" iyz="-0.0" ixz="2e-06"/>
  </inertial>
  <visual>
    <origin xyz="0.045 -0.039268 -0.168232" rpy="0 0 0"/>
    <geometry>
      <mesh filename="file://$(find quad_robot_description)/meshes/bl_thigh_link_1.stl" scale="0.001 0.001 0.001"/>
    </geometry>
    <material name="silver"/>
  </visual>
  <collision>
    <origin xyz="0.045 -0.039268 -0.168232" rpy="0 0 0"/>
    <geometry>
      <mesh filename="file://$(find quad_robot_description)/meshes/bl_thigh_link_1.stl" scale="0.001 0.001 0.001"/>
    </geometry>
  </collision>
</link>

<link name="fr_thigh_link_1">
  <inertial>
    <origin xyz="-0.043327105090512935 -0.004403476010929275 -0.013857298738867652" rpy="0 0 0"/>
    <mass value="0.05920353755551319"/>
    <inertia ixx="1.4e-05" iyy="2.3e-05" izz="1.6e-05" ixy="0.0" iyz="0.0" ixz="-2e-06"/>
  </inertial>
  <visual>
    <origin xyz="0.095 -0.139268 -0.168232" rpy="0 0 0"/>
    <geometry>
      <mesh filename="file://$(find quad_robot_description)/meshes/fr_thigh_link_1.stl" scale="0.001 0.001 0.001"/>
    </geometry>
    <material name="silver"/>
  </visual>
  <collision>
    <origin xyz="0.095 -0.139268 -0.168232" rpy="0 0 0"/>
    <geometry>
      <mesh filename="file://$(find quad_robot_description)/meshes/fr_thigh_link_1.stl" scale="0.001 0.001 0.001"/>
    </geometry>
  </collision>
</link>

<link name="fr_leg_link_1">
  <inertial>
    <origin xyz="1.329492071988625e-14 -0.0062391045174579884 -0.01688630571952185" rpy="0 0 0"/>
    <mass value="0.057591261478765976"/>
    <inertia ixx="4.4e-05" iyy="4.3e-05" izz="8e-06" ixy="0.0" iyz="-3e-06" ixz="0.0"/>
  </inertial>
  <visual>
    <origin xyz="0.14 -0.166768 -0.153232" rpy="0 0 0"/>
    <geometry>
      <mesh filename="file://$(find quad_robot_description)/meshes/fr_leg_link_1.stl" scale="0.001 0.001 0.001"/>
    </geometry>
    <material name="silver"/>
  </visual>
  <collision>
    <origin xyz="0.14 -0.166768 -0.153232" rpy="0 0 0"/>
    <geometry>
      <mesh filename="file://$(find quad_robot_description)/meshes/fr_leg_link_1.stl" scale="0.001 0.001 0.001"/>
    </geometry>
  </collision>
</link>

<link name="fr_shin_link_1">
  <inertial>
    <origin xyz="9.547918011776346e-15 -0.004889601649175651 -0.03833090663339895" rpy="0 0 0"/>
    <mass value="0.07085398163397447"/>
    <inertia ixx="6e-05" iyy="5.8e-05" izz="9e-06" ixy="0.0" iyz="-0.0" ixz="-0.0"/>
  </inertial>
  <visual>
    <origin xyz="0.14 -0.176768 -0.090732" rpy="0 0 0"/>
    <geometry>
      <mesh filename="file://$(find quad_robot_description)/meshes/fr_shin_link_1.stl" scale="0.001 0.001 0.001"/>
    </geometry>
    <material name="silver"/>
  </visual>
  <collision>
    <origin xyz="0.14 -0.176768 -0.090732" rpy="0 0 0"/>
    <geometry>
      <mesh filename="file://$(find quad_robot_description)/meshes/fr_shin_link_1.stl" scale="0.001 0.001 0.001"/>
    </geometry>
  </collision>
</link>

<link name="br_thigh_link_1">
  <inertial>
    <origin xyz="0.043327105090512484 0.0005965239890702023 -0.01385729873886582" rpy="0 0 0"/>
    <mass value="0.05920353755551319"/>
    <inertia ixx="1.4e-05" iyy="2.3e-05" izz="1.6e-05" ixy="-0.0" iyz="0.0" ixz="2e-06"/>
  </inertial>
  <visual>
    <origin xyz="0.045 -0.139268 -0.168232" rpy="0 0 0"/>
    <geometry>
      <mesh filename="file://$(find quad_robot_description)/meshes/br_thigh_link_1.stl" scale="0.001 0.001 0.001"/>
    </geometry>
    <material name="silver"/>
  </visual>
  <collision>
    <origin xyz="0.045 -0.139268 -0.168232" rpy="0 0 0"/>
    <geometry>
      <mesh filename="file://$(find quad_robot_description)/meshes/br_thigh_link_1.stl" scale="0.001 0.001 0.001"/>
    </geometry>
  </collision>
</link>

<link name="fl_thigh_link_1">
  <inertial>
    <origin xyz="-0.043327105090508244 -0.0005974221436033794 -0.013857298738869095" rpy="0 0 0"/>
    <mass value="0.05920353755551325"/>
    <inertia ixx="1.4e-05" iyy="2.3e-05" izz="1.6e-05" ixy="-0.0" iyz="-0.0" ixz="-2e-06"/>
  </inertial>
  <visual>
    <origin xyz="0.095 -0.039268 -0.168232" rpy="0 0 0"/>
    <geometry>
      <mesh filename="file://$(find quad_robot_description)/meshes/fl_thigh_link_1.stl" scale="0.001 0.001 0.001"/>
    </geometry>
    <material name="silver"/>
  </visual>
  <collision>
    <origin xyz="0.095 -0.039268 -0.168232" rpy="0 0 0"/>
    <geometry>
      <mesh filename="file://$(find quad_robot_description)/meshes/fl_thigh_link_1.stl" scale="0.001 0.001 0.001"/>
    </geometry>
  </collision>
</link>

<link name="br_leg_link_1">
  <inertial>
    <origin xyz="1.4152029837641958e-14 -0.006239104517458266 -0.01688630571951996" rpy="0 0 0"/>
    <mass value="0.057591261478765976"/>
    <inertia ixx="4.4e-05" iyy="4.3e-05" izz="8e-06" ixy="0.0" iyz="-3e-06" ixz="0.0"/>
  </inertial>
  <visual>
    <origin xyz="0.0 -0.171768 -0.153232" rpy="0 0 0"/>
    <geometry>
      <mesh filename="file://$(find quad_robot_description)/meshes/br_leg_link_1.stl" scale="0.001 0.001 0.001"/>
    </geometry>
    <material name="silver"/>
  </visual>
  <collision>
    <origin xyz="0.0 -0.171768 -0.153232" rpy="0 0 0"/>
    <geometry>
      <mesh filename="file://$(find quad_robot_description)/meshes/br_leg_link_1.stl" scale="0.001 0.001 0.001"/>
    </geometry>
  </collision>
</link>

<link name="br_shin_link_1">
  <inertial>
    <origin xyz="6.78740034932346e-15 -0.004889601649175596 -0.03833090663339699" rpy="0 0 0"/>
    <mass value="0.07085398163397447"/>
    <inertia ixx="6e-05" iyy="5.8e-05" izz="9e-06" ixy="0.0" iyz="-0.0" ixz="-0.0"/>
  </inertial>
  <visual>
    <origin xyz="-0.0 -0.181768 -0.090732" rpy="0 0 0"/>
    <geometry>
      <mesh filename="file://$(find quad_robot_description)/meshes/br_shin_link_1.stl" scale="0.001 0.001 0.001"/>
    </geometry>
    <material name="silver"/>
  </visual>
  <collision>
    <origin xyz="-0.0 -0.181768 -0.090732" rpy="0 0 0"/>
    <geometry>
      <mesh filename="file://$(find quad_robot_description)/meshes/br_shin_link_1.stl" scale="0.001 0.001 0.001"/>
    </geometry>
  </collision>
</link>

<link name="fl_leg_link_1">
  <inertial>
    <origin xyz="1.915134717478395e-14 0.00623820636292575 -0.016886305719524125" rpy="0 0 0"/>
    <mass value="0.057591261478765976"/>
    <inertia ixx="4.4e-05" iyy="4.3e-05" izz="8e-06" ixy="0.0" iyz="3e-06" ixz="0.0"/>
  </inertial>
  <visual>
    <origin xyz="0.14 -0.006768 -0.153232" rpy="0 0 0"/>
    <geometry>
      <mesh filename="file://$(find quad_robot_description)/meshes/fl_leg_link_1.stl" scale="0.001 0.001 0.001"/>
    </geometry>
    <material name="silver"/>
  </visual>
  <collision>
    <origin xyz="0.14 -0.006768 -0.153232" rpy="0 0 0"/>
    <geometry>
      <mesh filename="file://$(find quad_robot_description)/meshes/fl_leg_link_1.stl" scale="0.001 0.001 0.001"/>
    </geometry>
  </collision>
</link>

<link name="fl_shin_link_1">
  <inertial>
    <origin xyz="1.1796119636642288e-14 0.00488870349464599 -0.038330906633401565" rpy="0 0 0"/>
    <mass value="0.07085398163397423"/>
    <inertia ixx="6e-05" iyy="5.8e-05" izz="9e-06" ixy="0.0" iyz="0.0" ixz="-0.0"/>
  </inertial>
  <visual>
    <origin xyz="0.14 0.003232 -0.090732" rpy="0 0 0"/>
    <geometry>
      <mesh filename="file://$(find quad_robot_description)/meshes/fl_shin_link_1.stl" scale="0.001 0.001 0.001"/>
    </geometry>
    <material name="silver"/>
  </visual>
  <collision>
    <origin xyz="0.14 0.003232 -0.090732" rpy="0 0 0"/>
    <geometry>
      <mesh filename="file://$(find quad_robot_description)/meshes/fl_shin_link_1.stl" scale="0.001 0.001 0.001"/>
    </geometry>
  </collision>
</link>

<joint name="bl_shin_link_to_bl_leg_link" type="revolute">
  <origin xyz="0.0 -0.01 -0.0625" rpy="0 0 0"/>
  <parent link="bl_leg_link_1"/>
  <child link="bl_shin_link_1"/>
  <axis xyz="-0.0 1.0 -0.0"/>
  <limit upper="1.570796" lower="-1.570796" effort="100" velocity="100"/>
</joint>

<joint name="bl_leg_link_to_bl_thigh_link" type="revolute">
  <origin xyz="0.045 -0.0325 -0.015" rpy="0 0 0"/>
  <parent link="bl_thigh_link_1"/>
  <child link="bl_leg_link_1"/>
  <axis xyz="0.0 -1.0 0.0"/>
  <limit upper="1.570796" lower="-1.570796" effort="100" velocity="100"/>
</joint>

<joint name="bl_thigh_link_to_base_link" type="revolute">
  <origin xyz="-0.045 0.039268 0.168232" rpy="0 0 0"/>
  <parent link="base_link"/>
  <child link="bl_thigh_link_1"/>
  <axis xyz="1.0 0.0 0.0"/>
  <limit upper="1.570796" lower="-1.570796" effort="100" velocity="100"/>
</joint>

<joint name="fr_thigh_link_to_base_link" type="revolute">
  <origin xyz="-0.095 0.139268 0.168232" rpy="0 0 0"/>
  <parent link="base_link"/>
  <child link="fr_thigh_link_1"/>
  <axis xyz="1.0 0.0 0.0"/>
  <limit upper="1.570796" lower="-1.570796" effort="100" velocity="100"/>
</joint>

<joint name="fr_leg_link_to_fr_thigh_link" type="revolute">
  <origin xyz="-0.045 0.0275 -0.015" rpy="0 0 0"/>
  <parent link="fr_thigh_link_1"/>
  <child link="fr_leg_link_1"/>
  <axis xyz="0.0 1.0 0.0"/>
  <limit upper="1.570796" lower="-1.570796" effort="100" velocity="100"/>
</joint>

<joint name="fr_shin_link_to_fr_leg_link" type="revolute">
  <origin xyz="0.0 0.01 -0.0625" rpy="0 0 0"/>
  <parent link="fr_leg_link_1"/>
  <child link="fr_shin_link_1"/>
  <axis xyz="0.0 1.0 0.0"/>
  <limit upper="1.570796" lower="-1.570796" effort="100" velocity="100"/>
</joint>

<joint name="br_thigh_link_to_base_link" type="revolute">
  <origin xyz="-0.045 0.139268 0.168232" rpy="0 0 0"/>
  <parent link="base_link"/>
  <child link="br_thigh_link_1"/>
  <axis xyz="-1.0 -0.0 -0.0"/>
  <limit upper="1.570796" lower="-1.570796" effort="100" velocity="100"/>
</joint>

<joint name="fl_thigh_link_to_base_link" type="revolute">
  <origin xyz="-0.095 0.039268 0.168232" rpy="0 0 0"/>
  <parent link="base_link"/>
  <child link="fl_thigh_link_1"/>
  <axis xyz="1.0 0.0 0.0"/>
  <limit upper="1.570796" lower="-1.570796" effort="100" velocity="100"/>
</joint>

<joint name="br_leg_link_to_br_thigh_link" type="revolute">
  <origin xyz="0.045 0.0325 -0.015" rpy="0 0 0"/>
  <parent link="br_thigh_link_1"/>
  <child link="br_leg_link_1"/>
  <axis xyz="0.0 -1.0 -0.0"/>
  <limit upper="1.570796" lower="-1.570796" effort="100" velocity="100"/>
</joint>

<joint name="br_shin_link_to_br_leg_link" type="revolute">
  <origin xyz="0.0 0.01 -0.0625" rpy="0 0 0"/>
  <parent link="br_leg_link_1"/>
  <child link="br_shin_link_1"/>
  <axis xyz="0.0 1.0 0.0"/>
  <limit upper="1.570796" lower="-1.570796" effort="100" velocity="100"/>
</joint>

<joint name="fl_leg_link_to_fl_thigh_link" type="revolute">
  <origin xyz="-0.045 -0.0325 -0.015" rpy="0 0 0"/>
  <parent link="fl_thigh_link_1"/>
  <child link="fl_leg_link_1"/>
  <axis xyz="-0.0 1.0 0.0"/>
  <limit upper="1.570796" lower="-1.570796" effort="100" velocity="100"/>
</joint>

<joint name="fl_shin_link_to_fl_leg_link" type="revolute">
  <origin xyz="0.0 -0.01 -0.0625" rpy="0 0 0"/>
  <parent link="fl_leg_link_1"/>
  <child link="fl_shin_link_1"/>
  <axis xyz="0.0 1.0 0.0"/>
  <limit upper="1.570796" lower="-1.570796" effort="100" velocity="100"/>
</joint>

</robot>
